Workbook
Name Срез_Товарная_группа1: #N/A

Sheet Справочник_Каталог
A1: Наименование | B1: Товарная группа | C1: Цена | D1: Артикул
A2: Кресло «Райское наслаждение» | B2: Кресла | C2: 7490 | D2: VN17-40
A3: Покрывало «Прованс» | B3: Текстиль | C3: 2990 | D3: HN47-96
A4: Кухонный гарнитур «Прованс» | B4: Кухня | C4: 274900 | D4: DN45-68
A5: Обеденный стол «Трапеза» | B5: Столы | C5: 10490 | D5: BE65-00
A6: Угловой диван-кровать «Эвита» | B6: Диваны | C6: 65990 | D6: DF45-08
A7: Журнальный столик «Таурус» | B7: Столы | C7: 5990 | D7: BY65-24
A8: Письменный стол «Тандем» | B8: Столы | C8: 9590 | D8: WE25-48
A9: Стеллаж «Канкун» | B9: Стеллажи | C9: 2990 | D9: MN56-32
A10: Тумба деревянная «Альба» | B10: Столы | C10: 3590 | D10: KE35-92
A11: Подсвечник декоративный | B11: Декор | C11: 750 | D11: VO65-25
A12: Комод «Бостон» | B12: Шкафы и комоды | C12: 3290 | D12: RT65-07
A13: Занавески «Морская волна» | B13: Текстиль | C13: 1290 | D13: MI56-74
... A27: Бра «Тайный свет» | B27: Свет | C27: 890 | D27: FP86-07

Sheet Продажи_исходные
A1: Наименование | B1: Цена | C1: Количество
A2: Кресло «Райское наслаждение» | B2: 7490 | C2: 16
A3: Покрывало «Прованс» | B3: 2990 | C3: 23
A4: Кухонный гарнитур «Прованс» | B4: 274900 | C4: 5
A5: Обеденный стол «Трапеза» | B5: 10490 | C5: 3
A6: Угловой диван-кровать «Эвита» | B6: 65990 | C6: 3
A7: Журнальный столик «Таурус» | B7: 5990 | C7: 9
A8: Письменный стол «Тандем» | B8: 9590 | C8: 16
A9: Стеллаж «Канкун» | B9: 2990 | C9: 13
A10: Тумба деревянная «Альба» | B10: 3590 | C10: 5
A11: Подсвечник декоративный | B11: 750 | C11: 12
A12: Комод «Бостон» | B12: 3290 | C12: 7
A13: Занавески «Морская волна» | B13: 1290 | C13: 16
... A27: Бра «Тайный свет» | B27: 890 | C27: 26

Sheet ВПР_результат
A1: Артикул | B1: Наименование | C1: Товарная группа | D1: Цена | E1: Количество | G1: Ценовой сегмент | H1: Кол-во товаров
A2: =VLOOKUP($B2,Справочник_Каталог!$A:$D,4,0) -> VN17-40 | B2: Кресло «Райское наслаждение» | C2: =VLOOKUP($B2,Справочник_Каталог!$A:$D,2,0) -> Кресла | D2: 7490 | E2: =VLOOKUP($B2,Продажи_исходные!$A:$C,3,0) -> 16 | G2: До 1 000 ₽ | H2: =COUNTIF(ВПР_результат!D:D,"<1000") -> 5
A3: =VLOOKUP($B3,Справочник_Каталог!$A:$D,4,0) -> HN47-96 | B3: Покрывало «Прованс» | C3: =VLOOKUP($B3,Справочник_Каталог!$A:$D,2,0) -> Текстиль | D3: 2990 | E3: =VLOOKUP($B3,Продажи_исходные!$A:$C,3,0) -> 23 | G3: 1 000 - 10 000 ₽ | H3: =COUNTIFS(ВПР_результат!D:D,">=1000",ВПР_результат!D:D,"<10000") -> 17
A4: =VLOOKUP($B4,Справочник_Каталог!$A:$D,4,0) -> VR75-03 | B4: Набор подушек декоративных | C4: =VLOOKUP($B4,Справочник_Каталог!$A:$D,2,0) -> Декор | D4: 5690 | E4: =VLOOKUP($B4,Продажи_исходные!$A:$C,3,0) -> 8 | G4: 10 000 - 100 000 ₽ | H4: =COUNTIFS(ВПР_результат!D:D,">=10000",ВПР_результат!D:D,"<100000") -> 3
A5: =VLOOKUP($B5,Справочник_Каталог!$A:$D,4,0) -> OP87-04 | B5: Массажный коврик | C5: =VLOOKUP($B5,Справочник_Каталог!$A:$D,2,0) -> Декор | D5: 1490 | E5: =VLOOKUP($B5,Продажи_исходные!$A:$C,3,0) -> 37 | G5: Свыше 100 000 ₽ | H5: =COUNTIF(ВПР_результат!D:D,">=100000") -> 1
A6: =VLOOKUP($B6,Справочник_Каталог!$A:$D,4,0) -> DN45-68 | B6: Кухонный гарнитур «Прованс» | C6: =VLOOKUP($B6,Справочник_Каталог!$A:$D,2,0) -> Кухня | D6: 274900 | E6: =VLOOKUP($B6,Продажи_исходные!$A:$C,3,0) -> 5
A7: =VLOOKUP($B7,Справочник_Каталог!$A:$D,4,0) -> BE65-00 | B7: Обеденный стол «Трапеза» | C7: =VLOOKUP($B7,Справочник_Каталог!$A:$D,2,0) -> Столы | D7: 10490 | E7: =VLOOKUP($B7,Продажи_исходные!$A:$C,3,0) -> 3
A8: =VLOOKUP($B8,Справочник_Каталог!$A:$D,4,0) -> WP25-38 | B8: Торшер «Альфредо» | C8: =VLOOKUP($B8,Справочник_Каталог!$A:$D,2,0) -> Свет | D8: 3290 | E8: =VLOOKUP($B8,Продажи_исходные!$A:$C,3,0) -> 21
A9: =VLOOKUP($B9,Справочник_Каталог!$A:$D,4,0) -> MI56-74 | B9: Занавески «Морская волна» | C9: =VLOOKUP($B9,Справочник_Каталог!$A:$D,2,0) -> Текстиль | D9: 1290 | E9: =VLOOKUP($B9,Продажи_исходные!$A:$C,3,0) -> 16
A10: =VLOOKUP($B10,Справочник_Каталог!$A:$D,4,0) -> VU50-74 | B10: Кронштейн однорядный | C10: =VLOOKUP($B10,Справочник_Каталог!$A:$D,2,0) -> Фурнитура | D10: 99 | E10: =VLOOKUP($B10,Продажи_исходные!$A:$C,3,0) -> 54
A11: =VLOOKUP($B11,Справочник_Каталог!$A:$D,4,0) -> FY33-47 | B11: Карниз металлический | C11: =VLOOKUP($B11,Справочник_Каталог!$A:$D,2,0) -> Фурнитура | D11: 259 | E11: =VLOOKUP($B11,Продажи_исходные!$A:$C,3,0) -> 5
A12: =VLOOKUP($B12,Справочник_Каталог!$A:$D,4,0) -> DP86-95 | B12: Душевая кабина «Эрлит» | C12: =VLOOKUP($B12,Справочник_Каталог!$A:$D,2,0) -> Ванны | D12: 15690 | E12: =VLOOKUP($B12,Продажи_исходные!$A:$C,3,0) -> 2
A13: =VLOOKUP($B13,Справочник_Каталог!$A:$D,4,0) -> KO35-95 | B13: Смеситель «Посейдон» | C13: =VLOOKUP($B13,Справочник_Каталог!$A:$D,2,0) -> Фурнитура | D13: 4490 | E13: =VLOOKUP($B13,Продажи_исходные!$A:$C,3,0) -> 31
A14: =VLOOKUP($B14,Справочник_Каталог!$A:$D,4,0) -> VT65-74 | B14: Навесная полка «Оливия» | C14: =VLOOKUP($B14,Справочник_Каталог!$A:$D,2,0) -> Мебель | D14: 590 | E14: =VLOOKUP($B14,Продажи_исходные!$A:$C,3,0) -> 12
A15: =VLOOKUP($B15,Справочник_Каталог!$A:$D,4,0) -> FP86-07 | B15: Бра «Тайный свет» | C15: =VLOOKUP($B15,Справочник_Каталог!$A:$D,2,0) -> Свет | D15: 890 | E15: =VLOOKUP($B15,Продажи_исходные!$A:$C,3,0) -> 26
A16: =VLOOKUP($B16,Справочник_Каталог!$A:$D,4,0) -> WM32-27 | B16: Этажерка 3-ярусная | C16: =VLOOKUP($B16,Справочник_Каталог!$A:$D,2,0) -> Стеллажи | D16: 1390 | E16: =VLOOKUP($B16,Продажи_исходные!$A:$C,3,0) -> 9
A17: =VLOOKUP($B17,Справочник_Каталог!$A:$D,4,0) -> YT76-80 | B17: Набор органайзеров 5шт. | C17: =VLOOKUP($B17,Справочник_Каталог!$A:$D,2,0) -> Декор | D17: 1290 | E17: =VLOOKUP($B17,Продажи_исходные!$A:$C,3,0) -> 4
... A27: =VLOOKUP($B27,Справочник_Каталог!$A:$D,4,0) -> VO65-25 | B27: Подсвечник декоративный | C27: =VLOOKUP($B27,Справочник_Каталог!$A:$D,2,0) -> Декор | D27: 750 | E27: =VLOOKUP($B27,Продажи_исходные!$A:$C,3,0) -> 12

Sheet Анализ_СУММЕСЛИ
A1: Артикул | B1: Наименование | C1: Товарная группа | D1: Цена | E1: Количество | F1: Выручка
A2: =VLOOKUP($B2,Справочник_Каталог!$A:$D,4,0) -> DP86-95 | B2: Душевая кабина «Эрлит» | C2: =VLOOKUP($B2,Справочник_Каталог!$A:$D,2,0) -> Ванны | D2: 15690 | E2: =VLOOKUP($B2,Продажи_исходные!$A:$C,3,0) -> 2 | F2: =D2*E2 -> 31380
G3: Общая выручка | H3: =SUMIF(C:C,"Ванны",F:F) -> 31380
A5: =VLOOKUP($B5,Справочник_Каталог!$A:$D,4,0) -> VR75-03 | B5: Набор подушек декоративных | C5: =VLOOKUP($B5,Справочник_Каталог!$A:$D,2,0) -> Декор | D5: 5690 | E5: =VLOOKUP($B5,Продажи_исходные!$A:$C,3,0) -> 8 | F5: =D5*E5 -> 45520
A6: =VLOOKUP($B6,Справочник_Каталог!$A:$D,4,0) -> OP87-04 | B6: Массажный коврик | C6: =VLOOKUP($B6,Справочник_Каталог!$A:$D,2,0) -> Декор | D6: 1490 | E6: =VLOOKUP($B6,Продажи_исходные!$A:$C,3,0) -> 37 | F6: =D6*E6 -> 55130
A7: =VLOOKUP($B7,Справочник_Каталог!$A:$D,4,0) -> YT76-80 | B7: Набор органайзеров 5шт. | C7: =VLOOKUP($B7,Справочник_Каталог!$A:$D,2,0) -> Декор | D7: 1290 | E7: =VLOOKUP($B7,Продажи_исходные!$A:$C,3,0) -> 4 | F7: =D7*E7 -> 5160
A8: =VLOOKUP($B8,Справочник_Каталог!$A:$D,4,0) -> DE86-95 | B8: Панно декоративное «Африка» | C8: =VLOOKUP($B8,Справочник_Каталог!$A:$D,2,0) -> Декор | D8: 7890 | E8: =VLOOKUP($B8,Продажи_исходные!$A:$C,3,0) -> 17 | F8: =D8*E8 -> 134130
A9: =VLOOKUP($B9,Справочник_Каталог!$A:$D,4,0) -> VO65-25 | B9: Подсвечник декоративный | C9: =VLOOKUP($B9,Справочник_Каталог!$A:$D,2,0) -> Декор | D9: 750 | E9: =VLOOKUP($B9,Продажи_исходные!$A:$C,3,0) -> 12 | F9: =D9*E9 -> 9000
G10: Общая выручка | H10: =SUMIF(C:C,"Декор",F:F) -> 248940
G11: Всего наименований в группе «Декор» | H11: =COUNTIF(C:C,"Декор") -> 5
G12: Количество единиц по группе «Декор» (1,5-8 тыс. руб.) | H12: =SUMIFS(E:E,C:C,"Декор",D:D,">1500",D:D,"<8000") -> 25
A14: =VLOOKUP($B14,Справочник_Каталог!$A:$D,4,0) -> DF45-08 | B14: Угловой диван-кровать «Эвита» | C14: =VLOOKUP($B14,Справочник_Каталог!$A:$D,2,0) -> Диваны | D14: 65990 | E14: =VLOOKUP($B14,Продажи_исходные!$A:$C,3,0) -> 3 | F14: =D14*E14 -> 197970
G15: Общая выручка | H15: =SUMIF(C:C,"Диваны",F:F) -> 197970
A17: =VLOOKUP($B17,Справочник_Каталог!$A:$D,4,0) -> VN17-40 | B17: Кресло «Райское наслаждение» | C17: =VLOOKUP($B17,Справочник_Каталог!$A:$D,2,0) -> Кресла | D17: 7490 | E17: =VLOOKUP($B17,Продажи_исходные!$A:$C,3,0) -> 16 | F17: =D17*E17 -> 119840
G18: Общая выручка | H18: =SUMIF(C:C,"Кресла",F:F) -> 119840
A20: =VLOOKUP($B20,Справочник_Каталог!$A:$D,4,0) -> DN45-68 | B20: Кухонный гарнитур «Прованс» | C20: =VLOOKUP($B20,Справочник_Каталог!$A:$D,2,0) -> Кухня | D20: 274900 | E20: =VLOOKUP($B20,Продажи_исходные!$A:$C,3,0) -> 5 | F20: =D20*E20 -> 1374500
G21: Общая выручка | H21: =SUMIF(C:C,"Кухня",F:F) -> 1374500
A23: =VLOOKUP($B23,Справочник_Каталог!$A:$D,4,0) -> VT65-74 | B23: Навесная полка «Оливия» | C23: =VLOOKUP($B23,Справочник_Каталог!$A:$D,2,0) -> Мебель | D23: 590 | E23: =VLOOKUP($B23,Продажи_исходные!$A:$C,3,0) -> 12 | F23: =D23*E23 -> 7080
G24: Общая выручка | H24: =SUMIF(C:C,"Мебель",F:F) -> 7080
A26: =VLOOKUP($B26,Справочник_Каталог!$A:$D,4,0) -> WP25-38 | B26: Торшер «Альфредо» | C26: =VLOOKUP($B26,Справочник_Каталог!$A:$D,2,0) -> Свет | D26: 3290 | E26: =VLOOKUP($B26,Продажи_исходные!$A:$C,3,0) -> 21 | F26: =D26*E26 -> 69090
A27: =VLOOKUP($B27,Справочник_Каталог!$A:$D,4,0) -> FP86-07 | B27: Бра «Тайный свет» | C27: =VLOOKUP($B27,Справочник_Каталог!$A:$D,2,0) -> Свет | D27: 890 | E27: =VLOOKUP($B27,Продажи_исходные!$A:$C,3,0) -> 26 | F27: =D27*E27 -> 23140
G28: Общая выручка | H28: =SUMIF(C:C,"Свет",F:F) -> 92230
G29: Всего наименований в группе «Свет» | H29: =COUNTIF(C:C,"Свет") -> 2
G30: Количество единиц по группе «Свет» (1-5 тыс. руб.) | H30: =SUMIFS(E:E,C:C,"Свет",D:D,">1000",D:D,"<5000") -> 21
A32: =VLOOKUP($B32,Справочник_Каталог!$A:$D,4,0) -> WM32-27 | B32: Этажерка 3-ярусная | C32: =VLOOKUP($B32,Справочник_Каталог!$A:$D,2,0) -> Стеллажи | D32: 1390 | E32: =VLOOKUP($B32,Продажи_исходные!$A:$C,3,0) -> 9 | F32: =D32*E32 -> 12510
A33: =VLOOKUP($B33,Справочник_Каталог!$A:$D,4,0) -> MN56-32 | B33: Стеллаж «Канкун» | C33: =VLOOKUP($B33,Справочник_Каталог!$A:$D,2,0) -> Стеллажи | D33: 2990 | E33: =VLOOKUP($B33,Продажи_исходные!$A:$C,3,0) -> 13 | F33: =D33*E33 -> 38870
G34: Общая выручка | H34: =SUMIF(C:C,"Стеллажи",F:F) -> 51380
G35: Всего наименований в группе «Стеллажи» | H35: =COUNTIF(C:C,"Стеллажи") -> 2
G36: Количество единиц по группе «Стеллажи» (1-10 тыс. руб.) | H36: =SUMIFS(E:E,C:C,"Стеллажи",D:D,">1000",D:D,"<10000") -> 22
A38: =VLOOKUP($B38,Справочник_Каталог!$A:$D,4,0) -> BE65-00 | B38: Обеденный стол «Трапеза» | C38: =VLOOKUP($B38,Справочник_Каталог!$A:$D,2,0) -> Столы | D38: 10490 | E38: =VLOOKUP($B38,Продажи_исходные!$A:$C,3,0) -> 3 | F38: =D38*E38 -> 31470
A39: =VLOOKUP($B39,Справочник_Каталог!$A:$D,4,0) -> BY65-24 | B39: Журнальный столик «Таурус» | C39: =VLOOKUP($B39,Справочник_Каталог!$A:$D,2,0) -> Столы | D39: 5990 | E39: =VLOOKUP($B39,Продажи_исходные!$A:$C,3,0) -> 9 | F39: =D39*E39 -> 53910
A40: =VLOOKUP($B40,Справочник_Каталог!$A:$D,4,0) -> WE25-48 | B40: Письменный стол «Тандем» | C40: =VLOOKUP($B40,Справочник_Каталог!$A:$D,2,0) -> Столы | D40: 9590 | E40: =VLOOKUP($B40,Продажи_исходные!$A:$C,3,0) -> 16 | F40: =D40*E40 -> 153440
A41: =VLOOKUP($B41,Справочник_Каталог!$A:$D,4,0) -> KE35-92 | B41: Тумба деревянная «Альба» | C41: =VLOOKUP($B41,Справочник_Каталог!$A:$D,2,0) -> Столы | D41: 3590 | E41: =VLOOKUP($B41,Продажи_исходные!$A:$C,3,0) -> 5 | F41: =D41*E41 -> 17950
G42: Общая выручка | H42: =SUMIF(C:C,"Столы",F:F) -> 256770
G43: Всего наименований в группе «Столы» | H43: =COUNTIF(C:C,"Столы") -> 4
G44: Количество единиц по группе «Столы» (3-11 тыс. руб.) | H44: =SUMIFS(E:E,C:C,"Столы",D:D,">3000",D:D,"<11000") -> 33
A46: =VLOOKUP($B46,Справочник_Каталог!$A:$D,4,0) -> HN47-96 | B46: Покрывало «Прованс» | C46: =VLOOKUP($B46,Справочник_Каталог!$A:$D,2,0) -> Текстиль | D46: 2990 | E46: =VLOOKUP($B46,Продажи_исходные!$A:$C,3,0) -> 23 | F46: =D46*E46 -> 68770
A47: =VLOOKUP($B47,Справочник_Каталог!$A:$D,4,0) -> MI56-74 | B47: Занавески «Морская волна» | C47: =VLOOKUP($B47,Справочник_Каталог!$A:$D,2,0) -> Текстиль | D47: 1290 | E47: =VLOOKUP($B47,Продажи_исходные!$A:$C,3,0) -> 16 | F47: =D47*E47 -> 20640
A48: =VLOOKUP($B48,Справочник_Каталог!$A:$D,4,0) -> EP65-84 | B48: Постельное белье «Морская гладь» | C48: =VLOOKUP($B48,Справочник_Каталог!$A:$D,2,0) -> Текстиль | D48: 1290 | E48: =VLOOKUP($B48,Продажи_исходные!$A:$C,3,0) -> 19 | F48: =D48*E48 -> 24510
G49: Общая выручка | H49: =SUMIF(C:C,"Текстиль",F:F) -> 113920
...

Sheet Очистка_данных
A1: Проверка качества данных:
A2: Дубликаты | B2: Не найдены
A3: Пустые ячейки | B3: Не найдены
A4: Ошибки в формулах | B4: Не найдены
A5: Формат данных | B5: Корректный

Sheet Статистика
A1: ОБЩИЕ МЕТРИКИ
A2: Общая выручка | B2: =A23 -> 2718771
A3: Средний чек | B3: =AVERAGE(A11:A22) -> 226564.25
A4: Медиана | B4: =MEDIAN(A11:A22) -> 116880
A5: Максимальная продажа | B5: =MAX(A11:A22) -> 1374500
A6: Минимальная продажа | B6: =MIN(A11:A22) -> 7080
A7: Общее кол-во единиц | B7: =A24 -> 383
A10: Выручка | B10: Товарная группа | C10: % от общей
A11: 31380 | B11: Ванны | C11: =A11/A23 -> 0.01154198
A12: 248940 | B12: Декор | C12: =A12/A23 -> 0.091563431
A13: 197970 | B13: Диваны | C13: =A13/B2 -> 0.072815989
A14: 119840 | B14: Кресла | C14: =A14/A23 -> 0.04407874
A15: 1374500 | B15: Кухня | C15: =A15/A23 -> 0.50555931
A16: 7080 | B16: Мебель | C16: =A16/A23 -> 0.0026041178 | F16: Максимум | J16: Минимум
A17: 92230 | B17: Свет | C17: =A17/B2 -> 0.033923416 | E17: № | F17: Товар | G17: Выручка | I17: № | J17: Товар | K17: Выручка
A18: 51380 | B18: Стеллажи | C18: =A18/A23 -> 0.018898245 | E18: 1 | F18: =VLOOKUP(G18,A10:C24,2,0) -> Кухня | G18: =MAX(A11:A22) -> 1374500 | I18: 1 | J18: =VLOOKUP(K18,A10:C24,2,0) -> Мебель | K18: =MIN(A11:A22) -> 7080
A19: 256770 | B19: Столы | C19: =A19/A23 -> 0.094443408 | E19: 2 | F19: =VLOOKUP(G19,A11:C25,2,0) -> Столы | G19: =LARGE(A$11:A$22,E19) -> 256770 | I19: 2 | J19: =VLOOKUP(K19,A11:C25,2,0) -> Ванны | K19: =SMALL(A$11:A$22,I19) -> 31380
A20: 113920 | B20: Текстиль | C20: =A20/A23 -> 0.041901286 | E20: 3 | F20: =VLOOKUP(G20,A12:C26,2,0) -> Декор | G20: =LARGE(A$11:A$22,E20) -> 248940 | I20: 3 | J20: =VLOOKUP(K20,A12:C26,2,0) -> Стеллажи | K20: =SMALL(A$11:A$22,I20) -> 51380
A21: 145831 | B21: Фурнитура | C21: =A21/A23 -> 0.053638574 | E21: 4 | F21: =VLOOKUP(G21,A13:C27,2,0) -> Диваны | G21: =LARGE(A$11:A$22,E21) -> 197970 | I21: 4 | J21: =VLOOKUP(K21,A13:C27,2,0) -> Шкафы и комоды | K21: =SMALL(A$11:A$22,I21) -> 78930
A22: 78930 | B22: Шкафы и комоды | C22: =A22/A23 -> 0.0290315 | E22: 5 | F22: =VLOOKUP(G22,A14:C28,2,0) -> Фурнитура | G22: =LARGE(A$11:A$22,E22) -> 145831 | I22: 5 | J22: =VLOOKUP(K22,A14:C28,2,0) -> Свет | K22: =SMALL(A$11:A$22,I22) -> 92230
A23: =SUM(A11:A22) -> 2718771 | B23: Общая выручка | F23: Всего выручка топ-5 | G23: =SUM(G18:G22) -> 2224011 | J23: Всего выручка топ-5 | K23: =SUM(K18:K22) -> 261000
A24: 383 | B24: Всего продано, ед. | F24: Доля в общей выручке | G24: =G23/A23 -> 0.81802072 | J24: Доля в общей выручке | K24: =K23/A23 -> 0.095999258
A26: Товарная группа | B26: Выручка | C26: Среднее
A27: =B11 -> Ванны | B27: =A11 -> 31380 | C27: =AVERAGE(B27:B38) -> 226564.25
A28: =B12 -> Декор | B28: =A12 -> 248940 | C28: =AVERAGE(B27:B38) -> 226564.25
A29: =B13 -> Диваны | B29: =A13 -> 197970 | C29: =AVERAGE(B27:B38) -> 226564.25
A30: =B14 -> Кресла | B30: =A14 -> 119840 | C30: =AVERAGE(B27:B38) -> 226564.25
A31: =B15 -> Кухня | B31: =A15 -> 1374500 | C31: =AVERAGE(B27:B38) -> 226564.25
A32: =B16 -> Мебель | B32: =A16 -> 7080 | C32: =AVERAGE(B27:B38) -> 226564.25
A33: =B17 -> Свет | B33: =A17 -> 92230 | C33: =AVERAGE(B27:B38) -> 226564.25
A34: =B18 -> Стеллажи | B34: =A18 -> 51380 | C34: =AVERAGE(B27:B38) -> 226564.25
A35: =B19 -> Столы | B35: =A19 -> 256770 | C35: =AVERAGE(B27:B38) -> 226564.25
A36: =B20 -> Текстиль | B36: =A20 -> 113920 | C36: =AVERAGE(B27:B38) -> 226564.25
A37: =B21 -> Фурнитура | B37: =A21 -> 145831 | C37: =AVERAGE(B27:B38) -> 226564.25
A38: =B22 -> Шкафы и комоды | B38: =A22 -> 78930 | C38: =AVERAGE(B27:B38) -> 226564.25

Sheet Сводная_таблица
A1: Выручка | B1: Продано | C1: Средний чек | D1: Топ-категория "Кухня" (% от общей)
A2: =Статистика!B2 -> 2718771 | B2: =Статистика!B7 -> 383 | C2: =Статистика!B3 -> 226564.25 | D2: =Статистика!C15 -> 0.50555931
A52: Товарная группа | B52: Сумма по полю Выручка | C52: Сумма по полю Количество | D52: Количество по полю Наименование
A53: Ванны | B53: 31380 | C53: 2 | D53: 1
A54: Декор | B54: 248940 | C54: 78 | D54: 5
A55: Диваны | B55: 197970 | C55: 3 | D55: 1
A56: Кресла | B56: 119840 | C56: 16 | D56: 1
A57: Кухня | B57: 1374500 | C57: 5 | D57: 1
A58: Мебель | B58: 7080 | C58: 12 | D58: 1
A59: Свет | B59: 92230 | C59: 47 | D59: 2
A60: Стеллажи | B60: 51380 | C60: 22 | D60: 2
A61: Столы | B61: 256770 | C61: 33 | D61: 4
A62: Текстиль | B62: 113920 | C62: 58 | D62: 3
A63: Фурнитура | B63: 145831 | C63: 90 | D63: 3
A64: Шкафы и комоды | B64: 78930 | C64: 17 | D64: 2
A65: (пусто)
A66: Общий итог | B66: 2718771 | C66: 383 | D66: 26
A69: Товарная группа | B69: Сумма по полю Выручка | C69: Сумма по полю Среднее
A70: Ванны | B70: 31380 | C70: 226564.25
A71: Декор | B71: 248940 | C71: 226564.25
A72: Диваны | B72: 197970 | C72: 226564.25
A73: Кресла | B73: 119840 | C73: 226564.25
A74: Кухня | B74: 1374500 | C74: 226564.25
A75: Мебель | B75: 7080 | C75: 226564.25
A76: Свет | B76: 92230 | C76: 226564.25
A77: Стеллажи | B77: 51380 | C77: 226564.25
A78: Столы | B78: 256770 | C78: 226564.25
A79: Текстиль | B79: 113920 | C79: 226564.25
A80: Фурнитура | B80: 145831 | C80: 226564.25
A81: Шкафы и комоды | B81: 78930 | C81: 226564.25
A82: Общий итог | B82: 2718771 | C82: 2718771
A85: Товар | B85: Сумма по полю Выручка
A86: Декор | B86: 248940
A87: Диваны | B87: 197970
A88: Кухня | B88: 1374500
A89: Столы | B89: 256770
A90: Фурнитура | B90: 145831
A91: Общий итог | B91: 2224011
